1 1 2017
2 1 2017
3 1 2017
4 1 2017
5 1 2017
6 1 2017
7 1 2017
8 1 2017
9 1 2017
10 1 2017
11 1 2017
12 1 2017
13 1 2017
14 1 2017
15 1 2017
16 1 2017
17 1 2017
18 1 2017
19 1 2017
20 1 2017
21 1 2017
22 1 2017
23 1 2017
24 1 2017
25 1 2017
26 1 2017
27 1 2017
28 1 2017
29 1 2017
30 1 2017
31 1 2017
1 2 2017
2 2 2017
3 2 2017
4 2 2017
5 2 2017
6 2 2017
7 2 2017
8 2 2017
9 2 2017
10 2 2017
11 2 2017
12 2 2017
13 2 2017
14 2 2017
15 2 2017
16 2 2017
17 2 2017
18 2 2017
19 2 2017
20 2 2017
21 2 2017
22 2 2017
23 2 2017
24 2 2017
25 2 2017
26 2 2017
27 2 2017
28 2 2017
1 3 2017
2 3 2017
3 3 2017
4 3 2017
5 3 2017
6 3 2017
7 3 2017
8 3 2017
9 3 2017
10 3 2017
11 3 2017
12 3 2017
13 3 2017
14 3 2017
15 3 2017
16 3 2017
17 3 2017
18 3 2017
19 3 2017
20 3 2017
21 3 2017
22 3 2017
23 3 2017
24 3 2017
25 3 2017
26 3 2017
27 3 2017
28 3 2017
Traceback (most recent call last):
  File "/Users/wanqing/miniforge3/lib/python3.10/site-packages/urllib3/connectionpool.py", line 670, in urlopen
    httplib_response = self._make_request(
  File "/Users/wanqing/miniforge3/lib/python3.10/site-packages/urllib3/connectionpool.py", line 381, in _make_request
    self._validate_conn(conn)
  File "/Users/wanqing/miniforge3/lib/python3.10/site-packages/urllib3/connectionpool.py", line 976, in _validate_conn
    conn.connect()
  File "/Users/wanqing/miniforge3/lib/python3.10/site-packages/urllib3/connection.py", line 361, in connect
    self.sock = ssl_wrap_socket(
  File "/Users/wanqing/miniforge3/lib/python3.10/site-packages/urllib3/util/ssl_.py", line 377, in ssl_wrap_socket
    return context.wrap_socket(sock, server_hostname=server_hostname)
  File "/Users/wanqing/miniforge3/lib/python3.10/ssl.py", line 513, in wrap_socket
    return self.sslsocket_class._create(
  File "/Users/wanqing/miniforge3/lib/python3.10/ssl.py", line 1071, in _create
    self.do_handshake()
  File "/Users/wanqing/miniforge3/lib/python3.10/ssl.py", line 1342, in do_handshake
    self._sslobj.do_handshake()
ConnectionResetError: [Errno 54] Connection reset by peer

During handling of the above exception, another exception occurred:

Traceback (most recent call last):
  File "/Users/wanqing/miniforge3/lib/python3.10/site-packages/requests/adapters.py", line 489, in send
    resp = conn.urlopen(
  File "/Users/wanqing/miniforge3/lib/python3.10/site-packages/urllib3/connectionpool.py", line 724, in urlopen
    retries = retries.increment(
  File "/Users/wanqing/miniforge3/lib/python3.10/site-packages/urllib3/util/retry.py", line 403, in increment
    raise six.reraise(type(error), error, _stacktrace)
  File "/Users/wanqing/miniforge3/lib/python3.10/site-packages/urllib3/packages/six.py", line 734, in reraise
    raise value.with_traceback(tb)
  File "/Users/wanqing/miniforge3/lib/python3.10/site-packages/urllib3/connectionpool.py", line 670, in urlopen
    httplib_response = self._make_request(
  File "/Users/wanqing/miniforge3/lib/python3.10/site-packages/urllib3/connectionpool.py", line 381, in _make_request
    self._validate_conn(conn)
  File "/Users/wanqing/miniforge3/lib/python3.10/site-packages/urllib3/connectionpool.py", line 976, in _validate_conn
    conn.connect()
  File "/Users/wanqing/miniforge3/lib/python3.10/site-packages/urllib3/connection.py", line 361, in connect
    self.sock = ssl_wrap_socket(
  File "/Users/wanqing/miniforge3/lib/python3.10/site-packages/urllib3/util/ssl_.py", line 377, in ssl_wrap_socket
    return context.wrap_socket(sock, server_hostname=server_hostname)
  File "/Users/wanqing/miniforge3/lib/python3.10/ssl.py", line 513, in wrap_socket
    return self.sslsocket_class._create(
  File "/Users/wanqing/miniforge3/lib/python3.10/ssl.py", line 1071, in _create
    self.do_handshake()
  File "/Users/wanqing/miniforge3/lib/python3.10/ssl.py", line 1342, in do_handshake
    self._sslobj.do_handshake()
urllib3.exceptions.ProtocolError: ('Connection aborted.', ConnectionResetError(54, 'Connection reset by peer'))

During handling of the above exception, another exception occurred:

Traceback (most recent call last):
  File "/Users/wanqing/Downloads/Alphathon/scraping_news_articles/crawl.py", line 190, in <module>
    searching(year, waiting_time)
  File "/Users/wanqing/Downloads/Alphathon/scraping_news_articles/crawl.py", line 181, in searching
    scrap.get_elements_from_web(year, month, day, waiting_time)
  File "/Users/wanqing/Downloads/Alphathon/scraping_news_articles/crawl.py", line 66, in get_elements_from_web
    page = requests.get(title_url, headers=headers)
  File "/Users/wanqing/miniforge3/lib/python3.10/site-packages/requests/api.py", line 73, in get
    return request("get", url, params=params, **kwargs)
  File "/Users/wanqing/miniforge3/lib/python3.10/site-packages/requests/api.py", line 59, in request
    return session.request(method=method, url=url, **kwargs)
  File "/Users/wanqing/miniforge3/lib/python3.10/site-packages/requests/sessions.py", line 587, in request
    resp = self.send(prep, **send_kwargs)
  File "/Users/wanqing/miniforge3/lib/python3.10/site-packages/requests/sessions.py", line 701, in send
    r = adapter.send(request, **kwargs)
  File "/Users/wanqing/miniforge3/lib/python3.10/site-packages/requests/adapters.py", line 547, in send
    raise ConnectionError(err, request=request)
requests.exceptions.ConnectionError: ('Connection aborted.', ConnectionResetError(54, 'Connection reset by peer'))
